<?xml version="1.0" encoding="utf-8"?>
<!-- This URDF was automatically created by SolidWorks to URDF Exporter! Originally created by Stephen Brawner (brawner@gmail.com) 
     Commit Version: 1.6.0-4-g7f85cfe  Build Version: 1.6.7995.38578
     For more information, please see http://wiki.ros.org/sw_urdf_exporter -->
<robot
  name="practice3">
  <link
    name="base_link">
    <inertial>
      <origin
        xyz="0.018802 -0.00080218 -0.024014"
        rpy="0 0 0" />
      <mass
        value="8.3728" />
      <inertia
        ixx="0.015804"
        ixy="4.5204E-06"
        ixz="3.898E-05"
        iyy="0.015532"
        iyz="-3.1066E-05"
        izz="0.019652" />
    </inertial>
    <visual>
      <origin
        xyz="0 0 0"
        rpy="0 0 0" />
      <geometry>
        <mesh
          filename="package://practice3_urdf/meshes/base_link.STL" />
      </geometry>
      <material
        name="">
        <color
          rgba="0.89804 0.91765 0.92941 1" />
      </material>
    </visual>
    <collision>
      <origin
        xyz="0 0 0"
        rpy="0 0 0" />
      <geometry>
        <mesh
          filename="package://practice3_urdf/meshes/base_link.STL" />
      </geometry>
    </collision>
  </link>
  <link
    name="L_Hip_Link">
    <inertial>
      <origin
        xyz="0.082558 0.012109 0.013862"
        rpy="0 0 0" />
      <mass
        value="0.34413" />
      <inertia
        ixx="5.364E-05"
        ixy="-3.5954E-06"
        ixz="3.4903E-07"
        iyy="0.00079775"
        iyz="-2.3308E-07"
        izz="0.00084813" />
    </inertial>
    <visual>
      <origin
        xyz="0 0 0"
        rpy="0 0 0" />
      <geometry>
        <mesh
          filename="package://practice3_urdf/meshes/L_Hip_Link.STL" />
      </geometry>
      <material
        name="">
        <color
          rgba="1 0 0 1" />
      </material>
    </visual>
    <collision>
      <origin
        xyz="0 0 0"
        rpy="0 0 0" />
      <geometry>
        <mesh
          filename="package://practice3_urdf/meshes/L_Hip_Link.STL" />
      </geometry>
    </collision>
  </link>
  <joint
    name="L_Hip_Joint"
    type="revolute">
    <origin
      xyz="-0.057 0.16105 0"
      rpy="1.5708 1.5046 -3.1416" />
    <parent
      link="base_link" />
    <child
      link="L_Hip_Link" />
    <axis
      xyz="0 0 -1" />
    <limit
      lower="3.14"
      upper="0"
      effort="0"
      velocity="0" />
  </joint>
  <link
    name="L_Knee_Link">
    <inertial>
      <origin
        xyz="0.13316 -0.0017509 0.007828"
        rpy="0 0 0" />
      <mass
        value="0.30256" />
      <inertia
        ixx="0.00012851"
        ixy="4.7386E-06"
        ixz="7.3934E-07"
        iyy="0.0011269"
        iyz="-1.5721E-07"
        izz="0.0012369" />
    </inertial>
    <visual>
      <origin
        xyz="0 0 0"
        rpy="0 0 0" />
      <geometry>
        <mesh
          filename="package://practice3_urdf/meshes/L_Knee_Link.STL" />
      </geometry>
      <material
        name="">
        <color
          rgba="0 1 0 1" />
      </material>
    </visual>
    <collision>
      <origin
        xyz="0 0 0"
        rpy="0 0 0" />
      <geometry>
        <mesh
          filename="package://practice3_urdf/meshes/L_Knee_Link.STL" />
      </geometry>
    </collision>
  </link>
  <joint
    name="L_Knee_Joint"
    type="revolute">
    <origin
      xyz="0.17 0 0"
      rpy="0 0 -1.5608" />
    <parent
      link="L_Hip_Link" />
    <child
      link="L_Knee_Link" />
    <axis
      xyz="0 0 1" />
    <limit
      lower="0"
      upper="0"
      effort="0"
      velocity="0" />
  </joint>
  <link
    name="L_Wheel_Link">
    <inertial>
      <origin
        xyz="-1.3284E-13 -8.8232E-14 0.0025941"
        rpy="0 0 0" />
      <mass
        value="0.22735" />
      <inertia
        ixx="0.00021934"
        ixy="3.4704E-20"
        ixz="1.0147E-20"
        iyy="0.00021934"
        iyz="-7.4409E-21"
        izz="0.00043315" />
    </inertial>
    <visual>
      <origin
        xyz="0 0 0"
        rpy="0 0 0" />
      <geometry>
        <mesh
          filename="package://practice3_urdf/meshes/L_Wheel_Link.STL" />
      </geometry>
      <material
        name="">
        <color
          rgba="0 0 1 1" />
      </material>
    </visual>
    <collision>
      <origin
        xyz="0 0 0"
        rpy="0 0 0" />
      <geometry>
        <mesh
          filename="package://practice3_urdf/meshes/L_Wheel_Link.STL" />
      </geometry>
    </collision>
  </link>
  <joint
    name="L_Wheel_Joint"
    type="revolute">
    <origin
      xyz="0.2 0 0.0373"
      rpy="0 0 3.0655" />
    <parent
      link="L_Knee_Link" />
    <child
      link="L_Wheel_Link" />
    <axis
      xyz="0 0 1" />
    <limit
      lower="0"
      upper="0"
      effort="0"
      velocity="0" />
  </joint>
  <link
    name="R_Hip_Link">
    <inertial>
      <origin
        xyz="0.092683 0.0091301 -0.013657"
        rpy="0 0 0" />
      <mass
        value="0.33732" />
      <inertia
        ixx="5.2281E-05"
        ixy="-5.3934E-06"
        ixz="1.5918E-07"
        iyy="0.00079884"
        iyz="7.8101E-08"
        izz="0.00084811" />
    </inertial>
    <visual>
      <origin
        xyz="0 0 0"
        rpy="0 0 0" />
      <geometry>
        <mesh
          filename="package://practice3_urdf/meshes/R_Hip_Link.STL" />
      </geometry>
      <material
        name="">
        <color
          rgba="1 0 0 1" />
      </material>
    </visual>
    <collision>
      <origin
        xyz="0 0 0"
        rpy="0 0 0" />
      <geometry>
        <mesh
          filename="package://practice3_urdf/meshes/R_Hip_Link.STL" />
      </geometry>
    </collision>
  </link>
  <joint
    name="R_Hip_Joint"
    type="revolute">
    <origin
      xyz="-0.057 -0.16105 0"
      rpy="1.5708 0.60989 -3.1416" />
    <parent
      link="base_link" />
    <child
      link="R_Hip_Link" />
    <axis
      xyz="0 0 1" />
    <limit
      lower="0"
      upper="0"
      effort="0"
      velocity="0" />
  </joint>
  <link
    name="R_Knee_Link">
    <inertial>
      <origin
        xyz="0.13312 -0.0015753 -0.0078279"
        rpy="0 0 0" />
      <mass
        value="0.30256" />
      <inertia
        ixx="0.00012849"
        ixy="4.7645E-06"
        ixz="-6.9494E-07"
        iyy="0.0011269"
        iyz="-9.0885E-09"
        izz="0.0012369" />
    </inertial>
    <visual>
      <origin
        xyz="0 0 0"
        rpy="0 0 0" />
      <geometry>
        <mesh
          filename="package://practice3_urdf/meshes/R_Knee_Link.STL" />
      </geometry>
      <material
        name="">
        <color
          rgba="0 1 0 1" />
      </material>
    </visual>
    <collision>
      <origin
        xyz="0 0 0"
        rpy="0 0 0" />
      <geometry>
        <mesh
          filename="package://practice3_urdf/meshes/R_Knee_Link.STL" />
      </geometry>
    </collision>
  </link>
  <joint
    name="R_Knee_Joint"
    type="revolute">
    <origin
      xyz="0.17 0 0"
      rpy="0 0 -2.1771" />
    <parent
      link="R_Hip_Link" />
    <child
      link="R_Knee_Link" />
    <axis
      xyz="0 0 1" />
    <limit
      lower="0"
      upper="0"
      effort="0"
      velocity="0" />
  </joint>
  <link
    name="R_Wheel_Link">
    <inertial>
      <origin
        xyz="2.7756E-16 4.2327E-15 0.0022439"
        rpy="-3.1416 0 0" />
      <mass
        value="0.19406" />
      <inertia
        ixx="0.0002141"
        ixy="5.2333E-20"
        ixz="-1.0385E-21"
        iyy="0.0002141"
        iyz="1.4615E-20"
        izz="0.00042321" />
    </inertial>
    <visual>
      <origin
        xyz="0 0 0"
        rpy="-3.1416 0 0" />
      <geometry>
        <mesh
          filename="package://practice3_urdf/meshes/R_Wheel_Link.STL" />
      </geometry>
      <material
        name="">
        <color
          rgba="0 0 1 1" />
      </material>
    </visual>
    <collision>
      <origin
        xyz="0 0 0"
        rpy="0 0 0" />
      <geometry>
        <mesh
          filename="package://practice3_urdf/meshes/R_Wheel_Link.STL" />
      </geometry>
    </collision>
  </link>
  <joint
    name="R_Wheel_Joint"
    type="revolute">
    <origin
      xyz="0.2 0 -0.0373"
      rpy="0 0 2.787" />
    <parent
      link="R_Knee_Link" />
    <child
      link="R_Wheel_Link" />
    <axis
      xyz="0 0 1" />
    <limit
      lower="0"
      upper="0"
      effort="0"
      velocity="0" />
  </joint>
</robot>

 <mujoco>
        <compiler 
        meshdir="/home/linpc/PRACTICE-Simulator/practice_sim/src/practice3_urdf/meshes" 
        balanceinertia="true" 
        discardvisual="false" />
  </mujoco>
